Workbook

Sheet Start Here
A1: IRONMAN Cairns 2027 — 35-week plan (Andrew)
A2: 12 Oct 2026 → 13 Jun 2027 · 80/20 polarized · built 11 Oct 2026
A4: Key dates
A5: Wed–Fri 21–23 Oct 2026 | B5: Wedding week (Fri 23 Oct). Train Mon–Thu, Fri–Sat off, easy ride Sun 25 Oct.
A6: Mon 26 Oct 2026 | B6: Running returns: walk-run stage 1 (you passed 30 pain-free hops).
A7: Week 14 (11–17 Jan) | B7: Checkpoint: tibia + London go/no-go; FTP & CSS retests.
A8: Sun 21 Mar 2027 | B8: Gold Coast T100, 100km distance (2km / 80km / 18km). Your first triathlon and the half-distance tune-up.
A9: Sun 25 Apr 2027 | B9: London Marathon at Z2 (HR ≤149). Fly Wed 21 Apr; no road bike until Mon 10 May.
A10: Sun 13 Jun 2027 | B10: IRONMAN Cairns 🏁
A12: Goal: sub-11
A13: Target | B13: ~10:55: swim 1:05 · T1/T2 10' · bike 5:30 · run 4:10. Realistic today: ~11:30–12:15.
A14: What changes | B14: Volume stays the same (it's already near your 20h cap, and the tibia limits running). From week 15, IM power on long rides and Thursday blocks rises from 66–71% to 70–75% FTP. Every bike target scales with FTP, so retests raise them automatically.
A15: Biggest levers | B15: FTP to ~265–275W, a fitted TT bike by ~January with long rides in aero, and 90–100 g carbs/h on the bike.
A16: Decision | B16: Final race goal is set after the T100 test (21 Mar). Track FTP checkpoints on the Sub-11 tab.
A18: Recommendations (your Q3 & Q10)
A19: Lead-up races | B19: Yes, race once. Do the Gold Coast T100 100km race on Sun 21 Mar. It's at home, 12 weeks before Cairns, and the only chance to rehearse open-water mass starts, transitions and race fuelling. Race it controlled (see Calendar wk 23), not flat out, because London is 5 weeks later. If the wk-14 tibia check isn't clean, enter the Olympic distance on Sat 20 Mar instead. Optional: a local sprint in February for transition practice. Skip a separate 70.3: Geelong is on the same weekend as the T100.
A20: London block (21 Apr–9 May) | B20: Last ride Tue 20 Apr; the last long ride is Sat 17 Apr. In London, swim 3–4×/wk and lift 2×/wk. Use the gym's spin bike or Wattbike by heart rate (wks 29–30): it keeps your cycling legs and costs nothing. Marathon recovery: no running for 5 days, first run only if pain-free hopping. You return with ~5 weeks to Cairns, which is enough for a 2-week IM-specific block, a last big weekend and a 2-week taper.
A22: How the plan works
A23: Periodisation | B23: Transition (wks 1–2) → Base 1–3 (3–13) → Build 1–3 (15–27) → London (28–30) → Peak (31–33) → Taper (34–35). There's a recovery or test week roughly every 4th week: wks 6, 10, 14, 18, 22, 24.
A24: 10% rule | B24: No 'load' week's total hours go up more than 10% on the previous load week. Run km follow the same cap once continuous running is established (wk 9). Recovery, race and taper weeks are lower by design, so the first load week after one is compared with the last load week before it. Walk-run weeks 3–8 follow a return-to-run protocol instead, because 10% of zero is nothing. Weekly Summary shows the % change for every load week.
A25: 80/20 | B25: Most time is Z1–Z2. Hard work is Z4+ (bike VO2 and threshold, CSS swims, cruise intervals) with almost nothing in Z3. At this training age, time above Z2 sits at about 10% of training time; IM-power work sits at the top of Z2 power. Weekly Summary shows the high-intensity % for each week.
A26: Week shape | B26: Mon swim (or easy spin in open-water weeks) + easy run · Tue bike intervals, then Strength A later (hard day) · Wed CSS swim + run quality · Thu endurance bike + run · Fri long swim + Strength B · Sat long ride + brick · Sun long run + easy spin or open-water swim. Max 3 swims a week. Swims at midday; bikes and solo runs in the morning; on bike days the run is in the evening; gym in the evening (see the Calendar's When column). Weekdays ≤2h, two sessions on most days.
A27: Tibia rules | B27: Pain ≤2/10 during a run and nothing the next morning. If either fails, stop, take 2 days off and drop back one stage. Run on flat, soft surfaces at a slightly higher cadence, and use the soleus, tibialis and hop work in Strength A (bone loading). Run intensity only starts in wk 16, and only if the wk-14 checkpoint is clean. Any focal, pinpoint bone pain means seeing a sports doctor.
A28: Bike | B28: Zwift until your helmet, computer and Varia arrive. Then move the long rides outdoors at the same power. Practise the TT position as soon as the TT bike arrives (fit first).
A29: Swim | B29: 50m pool, so every rep is ≥50m and Apple Watch counts correctly. Open water starts in wk 17: buy the wetsuit by early February and do some non-wetsuit swims too.
A30: Nutrition | B30: Gut training. Long rides go 60→100 g carbs/h over the season (you've already managed 90 g/h running). Long runs 60–90 g/h. Sodium 500–1000 mg/h depending on sweat. Rehearse your exact race products at the T100 and London.
A31: Heat | B31: Cairns is warm and humid. Heat sessions start in wk 31: Zwift rides with no fan or an extra layer.
A32: Retests | B32: CSS: wks 6, 14, 18. FTP ramp: wks 6, 14, 22. After a test, update the yellow cells on the Zones tab. Calendar watt targets assume FTP 242W; scale them by your new FTP ÷ 242.
A33: Logging | B33: Tick the 'Done' column on the Calendar. Log FTP changes in Strava as 'FTP SET: [W]'.

Sheet Weekly Summary
A1: Week | B1: Week starts | C1: Phase | D1: Week type | E1: Focus | F1: Total h | G1: Swim h | H1: Bike h | I1: Run h | J1: Strength h | K1: Race h | L1: Swim km | M1: Run km | N1: Δ hours vs prev load wk | O1: Δ run km vs prev load wk | P1: High-intensity % (Z4+)
A2: 1 | B2: 46307 | C2: Transition | D2: load | E2: Post-holiday rebuild; swim & bike only (tibia still healing). | F2: =SUMIFS(Calendar!$G$2:$G$426,Calendar!$A$2:$A$426,$A2)/60 -> 7.6666667 | G2: =SUMIFS(Calendar!$G$2:$G$426,Calendar!$A$2:$A$426,$A2,Calendar!$E$2:$E$426,"Swim")/60 -> 2.4166667 | H2: =SUMIFS(Calendar!$G$2:$G$426,Calendar!$A$2:$A$426,$A2,Calendar!$E$2:$E$426,"Bike")/60 -> 4 | I2: =SUMIFS(Calendar!$G$2:$G$426,Calendar!$A$2:$A$426,$A2,Calendar!$E$2:$E$426,"Run")/60 -> 0 | J2: =SUMIFS(Calendar!$G$2:$G$426,Calendar!$A$2:$A$426,$A2,Calendar!$E$2:$E$426,"Strength")/60 -> 1.25 | K2: =SUMIFS(Calendar!$G$2:$G$426,Calendar!$A$2:$A$426,$A2,Calendar!$E$2:$E$426,"Race")/60 -> 0 | L2: =SUMIFS(Calendar!$H$2:$H$426,Calendar!$A$2:$A$426,$A2,Calendar!$E$2:$E$426,"Swim") -> 7.1 | M2: =SUMIFS(Calendar!$H$2:$H$426,Calendar!$A$2:$A$426,$A2,Calendar!$E$2:$E$426,"Run") -> 0 | N2: — | O2: — | P2: =IFERROR(SUMIFS(Calendar!$M$2:$M$426,Calendar!$A$2:$A$426,$A2)/((SUMIFS(Calendar!$G$2:$G$426,Calendar!$A$2:$A$426,$A2,Calendar!$E$2:$E$426,"Swim"))+(SUMIFS(Calendar!$G$2:$G$426,Calendar!$A$2:$A$426,$A2,Calendar!$E$2:$E$426,"Bike"))+(SUMIFS(Calendar!$G$2:$G$426,Calendar!$A$2:$A$426,$A2,Calendar!$E$2:$E$426,"Run"))),0) -> 0.090909091
A3: 2 | B3: 46314 | C3: Transition | D3: reduced | E3: Wedding week — light & fresh. Fri–Sat off; easy ride Sun. | F3: =SUMIFS(Calendar!$G$2:$G$426,Calendar!$A$2:$A$426,$A3)/60 -> 4.75 | G3: =SUMIFS(Calendar!$G$2:$G$426,Calendar!$A$2:$A$426,$A3,Calendar!$E$2:$E$426,"Swim")/60 -> 1.5 | H3: =SUMIFS(Calendar!$G$2:$G$426,Calendar!$A$2:$A$426,$A3,Calendar!$E$2:$E$426,"Bike")/60 -> 2.75 | I3: =SUMIFS(Calendar!$G$2:$G$426,Calendar!$A$2:$A$426,$A3,Calendar!$E$2:$E$426,"Run")/60 -> 0 | J3: =SUMIFS(Calendar!$G$2:$G$426,Calendar!$A$2:$A$426,$A3,Calendar!$E$2:$E$426,"Strength")/60 -> 0.5 | K3: =SUMIFS(Calendar!$G$2:$G$426,Calendar!$A$2:$A$426,$A3,Calendar!$E$2:$E$426,"Race")/60 -> 0 | L3: =SUMIFS(Calendar!$H$2:$H$426,Calendar!$A$2:$A$426,$A3,Calendar!$E$2:$E$426,"Swim") -> 4.3 | M3: =SUMIFS(Calendar!$H$2:$H$426,Calendar!$A$2:$A$426,$A3,Calendar!$E$2:$E$426,"Run") -> 0 | N3: — | O3: — | P3: =IFERROR(SUMIFS(Calendar!$M$2:$M$426,Calendar!$A$2:$A$426,$A3)/((SUMIFS(Calendar!$G$2:$G$426,Calendar!$A$2:$A$426,$A3,Calendar!$E$2:$E$426,"Swim"))+(SUMIFS(Calendar!$G$2:$G$426,Calendar!$A$2:$A$426,$A3,Calendar!$E$2:$E$426,"Bike"))+(SUMIFS(Calendar!$G$2:$G$426,Calendar!$A$2:$A$426,$A3,Calendar!$E$2:$E$426,"Run"))),0) -> 0.074509804
A4: 3 | B4: 46321 | C4: Base 1 | D4: load | E4: Run returns (walk-run stage 1, alternate days). Aerobic swim/bike base, VO2 touch on the bike. | F4: =SUMIFS(Calendar!$G$2:$G$426,Calendar!$A$2:$A$426,$A4)/60 -> 7.8333333 | G4: =SUMIFS(Calendar!$G$2:$G$426,Calendar!$A$2:$A$426,$A4,Calendar!$E$2:$E$426,"Swim")/60 -> 2.3333333 | H4: =SUMIFS(Calendar!$G$2:$G$426,Calendar!$A$2:$A$426,$A4,Calendar!$E$2:$E$426,"Bike")/60 -> 3.25 | I4: =SUMIFS(Calendar!$G$2:$G$426,Calendar!$A$2:$A$426,$A4,Calendar!$E$2:$E$426,"Run")/60 -> 1 | J4: =SUMIFS(Calendar!$G$2:$G$426,Calendar!$A$2:$A$426,$A4,Calendar!$E$2:$E$426,"Strength")/60 -> 1.25 | K4: =SUMIFS(Calendar!$G$2:$G$426,Calendar!$A$2:$A$426,$A4,Calendar!$E$2:$E$426,"Race")/60 -> 0 | L4: =SUMIFS(Calendar!$H$2:$H$426,Calendar!$A$2:$A$426,$A4,Calendar!$E$2:$E$426,"Swim") -> 6.8 | M4: =SUMIFS(Calendar!$H$2:$H$426,Calendar!$A$2:$A$426,$A4,Calendar!$E$2:$E$426,"Run") -> 3 | N4: =F4/F2-1 -> 0.02173913 | O4: — | P4: =IFERROR(SUMIFS(Calendar!$M$2:$M$426,Calendar!$A$2:$A$426,$A4)/((SUMIFS(Calendar!$G$2:$G$426,Calendar!$A$2:$A$426,$A4,Calendar!$E$2:$E$426,"Swim"))+(SUMIFS(Calendar!$G$2:$G$426,Calendar!$A$2:$A$426,$A4,Calendar!$E$2:$E$426,"Bike"))+(SUMIFS(Calendar!$G$2:$G$426,Calendar!$A$2:$A$426,$A4,Calendar!$E$2:$E$426,"Run"))),0) -> 0.096202532
A5: 4 | B5: 46328 | C5: Base 1 | D5: load | E5: Walk-run stage 2. | F5: =SUMIFS(Calendar!$G$2:$G$426,Calendar!$A$2:$A$426,$A5)/60 -> 8.5 | G5: =SUMIFS(Calendar!$G$2:$G$426,Calendar!$A$2:$A$426,$A5,Calendar!$E$2:$E$426,"Swim")/60 -> 2.5 | H5: =SUMIFS(Calendar!$G$2:$G$426,Calendar!$A$2:$A$426,$A5,Calendar!$E$2:$E$426,"Bike")/60 -> 3.5 | I5: =SUMIFS(Calendar!$G$2:$G$426,Calendar!$A$2:$A$426,$A5,Calendar!$E$2:$E$426,"Run")/60 -> 1.25 | J5: =SUMIFS(Calendar!$G$2:$G$426,Calendar!$A$2:$A$426,$A5,Calendar!$E$2:$E$426,"Strength")/60 -> 1.25 | K5: =SUMIFS(Calendar!$G$2:$G$426,Calendar!$A$2:$A$426,$A5,Calendar!$E$2:$E$426,"Race")/60 -> 0 | L5: =SUMIFS(Calendar!$H$2:$H$426,Calendar!$A$2:$A$426,$A5,Calendar!$E$2:$E$426,"Swim") -> 7.4 | M5: =SUMIFS(Calendar!$H$2:$H$426,Calendar!$A$2:$A$426,$A5,Calendar!$E$2:$E$426,"Run") -> 6 | N5: =F5/F4-1 -> 0.085106383 | O5: — | P5: =IFERROR(SUMIFS(Calendar!$M$2:$M$426,Calendar!$A$2:$A$426,$A5)/((SUMIFS(Calendar!$G$2:$G$426,Calendar!$A$2:$A$426,$A5,Calendar!$E$2:$E$426,"Swim"))+(SUMIFS(Calendar!$G$2:$G$426,Calendar!$A$2:$A$426,$A5,Calendar!$E$2:$E$426,"Bike"))+(SUMIFS(Calendar!$G$2:$G$426,Calendar!$A$2:$A$426,$A5,Calendar!$E$2:$E$426,"Run"))),0) -> 0.094252874
A6: 5 | B6: 46335 | C6: Base 1 | D6: load | E6: Walk-run stage 3. Biggest base-1 week. | F6: =SUMIFS(Calendar!$G$2:$G$426,Calendar!$A$2:$A$426,$A6)/60 -> 9.3333333 | G6: =SUMIFS(Calendar!$G$2:$G$426,Calendar!$A$2:$A$426,$A6,Calendar!$E$2:$E$426,"Swim")/60 -> 2.75 | H6: =SUMIFS(Calendar!$G$2:$G$426,Calendar!$A$2:$A$426,$A6,Calendar!$E$2:$E$426,"Bike")/60 -> 3.8333333 | I6: =SUMIFS(Calendar!$G$2:$G$426,Calendar!$A$2:$A$426,$A6,Calendar!$E$2:$E$426,"Run")/60 -> 1.5 | J6: =SUMIFS(Calendar!$G$2:$G$426,Calendar!$A$2:$A$426,$A6,Calendar!$E$2:$E$426,"Strength")/60 -> 1.25 | K6: =SUMIFS(Calendar!$G$2:$G$426,Calendar!$A$2:$A$426,$A6,Calendar!$E$2:$E$426,"Race")/60 -> 0 | L6: =SUMIFS(Calendar!$H$2:$H$426,Calendar!$A$2:$A$426,$A6,Calendar!$E$2:$E$426,"Swim") -> 8.2 | M6: =SUMIFS(Calendar!$H$2:$H$426,Calendar!$A$2:$A$426,$A6,Calendar!$E$2:$E$426,"Run") -> 9.9 | N6: =F6/F5-1 -> 0.098039216 | O6: — | P6: =IFERROR(SUMIFS(Calendar!$M$2:$M$426,Calendar!$A$2:$A$426,$A6)/((SUMIFS(Calendar!$G$2:$G$426,Calendar!$A$2:$A$426,$A6,Calendar!$E$2:$E$426,"Swim"))+(SUMIFS(Calendar!$G$2:$G$426,Calendar!$A$2:$A$426,$A6,Calendar!$E$2:$E$426,"Bike"))+(SUMIFS(Calendar!$G$2:$G$426,Calendar!$A$2:$A$426,$A6,Calendar!$E$2:$E$426,"Run"))),0) -> 0.094845361
A7: 6 | B7: 46342 | C7: Base 1 | D7: recovery | E7: Recovery + tests (CSS Wed, FTP ramp Sat). Hold walk-run stage 3. | F7: =SUMIFS(Calendar!$G$2:$G$426,Calendar!$A$2:$A$426,$A7)/60 -> 6.8333333 | G7: =SUMIFS(Calendar!$G$2:$G$426,Calendar!$A$2:$A$426,$A7,Calendar!$E$2:$E$426,"Swim")/60 -> 2.1666667 | H7: =SUMIFS(Calendar!$G$2:$G$426,Calendar!$A$2:$A$426,$A7,Calendar!$E$2:$E$426,"Bike")/60 -> 2.1666667 | I7: =SUMIFS(Calendar!$G$2:$G$426,Calendar!$A$2:$A$426,$A7,Calendar!$E$2:$E$426,"Run")/60 -> 1.5 | J7: =SUMIFS(Calendar!$G$2:$G$426,Calendar!$A$2:$A$426,$A7,Calendar!$E$2:$E$426,"Strength")/60 -> 1 | K7: =SUMIFS(Calendar!$G$2:$G$426,Calendar!$A$2:$A$426,$A7,Calendar!$E$2:$E$426,"Race")/60 -> 0 | L7: =SUMIFS(Calendar!$H$2:$H$426,Calendar!$A$2:$A$426,$A7,Calendar!$E$2:$E$426,"Swim") -> 5.8 | M7: =SUMIFS(Calendar!$H$2:$H$426,Calendar!$A$2:$A$426,$A7,Calendar!$E$2:$E$426,"Run") -> 9.9 | N7: — | O7: — | P7: =IFERROR(SUMIFS(Calendar!$M$2:$M$426,Calendar!$A$2:$A$426,$A7)/((SUMIFS(Calendar!$G$2:$G$426,Calendar!$A$2:$A$426,$A7,Calendar!$E$2:$E$426,"Swim"))+(SUMIFS(Calendar!$G$2:$G$426,Calendar!$A$2:$A$426,$A7,Calendar!$E$2:$E$426,"Bike"))+(SUMIFS(Calendar!$G$2:$G$426,Calendar!$A$2:$A$426,$A7,Calendar!$E$2:$E$426,"Run"))),0) -> 0.051428571
A8: 7 | B8: 46349 | C8: Base 2 | D8: load | E8: Walk-run stage 4, then continuous running next week. | F8: =SUMIFS(Calendar!$G$2:$G$426,Calendar!$A$2:$A$426,$A8)/60 -> 10.25 | G8: =SUMIFS(Calendar!$G$2:$G$426,Calendar!$A$2:$A$426,$A8,Calendar!$E$2:$E$426,"Swim")/60 -> 2.75 | H8: =SUMIFS(Calendar!$G$2:$G$426,Calendar!$A$2:$A$426,$A8,Calendar!$E$2:$E$426,"Bike")/60 -> 4.5833333 | I8: =SUMIFS(Calendar!$G$2:$G$426,Calendar!$A$2:$A$426,$A8,Calendar!$E$2:$E$426,"Run")/60 -> 1.5 | J8: =SUMIFS(Calendar!$G$2:$G$426,Calendar!$A$2:$A$426,$A8,Calendar!$E$2:$E$426,"Strength")/60 -> 1.4166667 | K8: =SUMIFS(Calendar!$G$2:$G$426,Calendar!$A$2:$A$426,$A8,Calendar!$E$2:$E$426,"Race")/60 -> 0 | L8: =SUMIFS(Calendar!$H$2:$H$426,Calendar!$A$2:$A$426,$A8,Calendar!$E$2:$E$426,"Swim") -> 8.2 | M8: =SUMIFS(Calendar!$H$2:$H$426,Calendar!$A$2:$A$426,$A8,Calendar!$E$2:$E$426,"Run") -> 12 | N8: =F8/F6-1 -> 0.098214286 | O8: — | P8: =IFERROR(SUMIFS(Calendar!$M$2:$M$426,Calendar!$A$2:$A$426,$A8)/((SUMIFS(Calendar!$G$2:$G$426,Calendar!$A$2:$A$426,$A8,Calendar!$E$2:$E$426,"Swim"))+(SUMIFS(Calendar!$G$2:$G$426,Calendar!$A$2:$A$426,$A8,Calendar!$E$2:$E$426,"Bike"))+(SUMIFS(Calendar!$G$2:$G$426,Calendar!$A$2:$A$426,$A8,Calendar!$E$2:$E$426,"Run"))),0) -> 0.094339623
A9: 8 | B9: 46356 | C9: Base 2 | D9: load | E9: First continuous runs (25–30'). Long ride 2h45. | F9: =SUMIFS(Calendar!$G$2:$G$426,Calendar!$A$2:$A$426,$A9)/60 -> 11.166667 | G9: =SUMIFS(Calendar!$G$2:$G$426,Calendar!$A$2:$A$426,$A9,Calendar!$E$2:$E$426,"Swim")/60 -> 3 | H9: =SUMIFS(Calendar!$G$2:$G$426,Calendar!$A$2:$A$426,$A9,Calendar!$E$2:$E$426,"Bike")/60 -> 5.3333333 | I9: =SUMIFS(Calendar!$G$2:$G$426,Calendar!$A$2:$A$426,$A9,Calendar!$E$2:$E$426,"Run")/60 -> 1.4166667 | J9: =SUMIFS(Calendar!$G$2:$G$426,Calendar!$A$2:$A$426,$A9,Calendar!$E$2:$E$426,"Strength")/60 -> 1.4166667 | K9: =SUMIFS(Calendar!$G$2:$G$426,Calendar!$A$2:$A$426,$A9,Calendar!$E$2:$E$426,"Race")/60 -> 0 | L9: =SUMIFS(Calendar!$H$2:$H$426,Calendar!$A$2:$A$426,$A9,Calendar!$E$2:$E$426,"Swim") -> 8.8 | M9: =SUMIFS(Calendar!$H$2:$H$426,Calendar!$A$2:$A$426,$A9,Calendar!$E$2:$E$426,"Run") -> 14.2 | N9: =F9/F8-1 -> 0.089430894 | O9: — | P9: =IFERROR(SUMIFS(Calendar!$M$2:$M$426,Calendar!$A$2:$A$426,$A9)/((SUMIFS(Calendar!$G$2:$G$426,Calendar!$A$2:$A$426,$A9,Calendar!$E$2:$E$426,"Swim"))+(SUMIFS(Calendar!$G$2:$G$426,Calendar!$A$2:$A$426,$A9,Calendar!$E$2:$E$426,"Bike"))+(SUMIFS(Calendar!$G$2:$G$426,Calendar!$A$2:$A$426,$A9,Calendar!$E$2:$E$426,"Run"))),0) -> 0.092307692
A10: 9 | B10: 46363 | C10: Base 2 | D10: load | E10: Continuous running established (4 runs incl. first brick). Run volume now capped at +10%/wk. | F10: =SUMIFS(Calendar!$G$2:$G$426,Calendar!$A$2:$A$426,$A10)/60 -> 12 | G10: =SUMIFS(Calendar!$G$2:$G$426,Calendar!$A$2:$A$426,$A10,Calendar!$E$2:$E$426,"Swim")/60 -> 3 | H10: =SUMIFS(Calendar!$G$2:$G$426,Calendar!$A$2:$A$426,$A10,Calendar!$E$2:$E$426,"Bike")/60 -> 5.75 | I10: =SUMIFS(Calendar!$G$2:$G$426,Calendar!$A$2:$A$426,$A10,Calendar!$E$2:$E$426,"Run")/60 -> 1.8333333 | J10: =SUMIFS(Calendar!$G$2:$G$426,Calendar!$A$2:$A$426,$A10,Calendar!$E$2:$E$426,"Strength")/60 -> 1.4166667 | K10: =SUMIFS(Calendar!$G$2:$G$426,Calendar!$A$2:$A$426,$A10,Calendar!$E$2:$E$426,"Race")/60 -> 0 | L10: =SUMIFS(Calendar!$H$2:$H$426,Calendar!$A$2:$A$426,$A10,Calendar!$E$2:$E$426,"Swim") -> 8.8 | M10: =SUMIFS(Calendar!$H$2:$H$426,Calendar!$A$2:$A$426,$A10,Calendar!$E$2:$E$426,"Run") -> 18.4 | N10: =F10/F9-1 -> 0.074626866 | O10: — | P10: =IFERROR(SUMIFS(Calendar!$M$2:$M$426,Calendar!$A$2:$A$426,$A10)/((SUMIFS(Calendar!$G$2:$G$426,Calendar!$A$2:$A$426,$A10,Calendar!$E$2:$E$426,"Swim"))+(SUMIFS(Calendar!$G$2:$G$426,Calendar!$A$2:$A$426,$A10,Calendar!$E$2:$E$426,"Bike"))+(SUMIFS(Calendar!$G$2:$G$426,Calendar!$A$2:$A$426,$A10,Calendar!$E$2:$E$426,"Run"))),0) -> 0.092913386
A11: 10 | B11: 46370 | C11: Base 2 | D11: recovery | E11: Recovery week (~70%). | F11: =SUMIFS(Calendar!$G$2:$G$426,Calendar!$A$2:$A$426,$A11)/60 -> 8.1666667 | G11: =SUMIFS(Calendar!$G$2:$G$426,Calendar!$A$2:$A$426,$A11,Calendar!$E$2:$E$426,"Swim")/60 -> 2.1666667 | H11: =SUMIFS(Calendar!$G$2:$G$426,Calendar!$A$2:$A$426,$A11,Calendar!$E$2:$E$426,"Bike")/60 -> 3.5 | I11: =SUMIFS(Calendar!$G$2:$G$426,Calendar!$A$2:$A$426,$A11,Calendar!$E$2:$E$426,"Run")/60 -> 1.5 | J11: =SUMIFS(Calendar!$G$2:$G$426,Calendar!$A$2:$A$426,$A11,Calendar!$E$2:$E$426,"Strength")/60 -> 1 | K11: =SUMIFS(Calendar!$G$2:$G$426,Calendar!$A$2:$A$426,$A11,Calendar!$E$2:$E$426,"Race")/60 -> 0 | L11: =SUMIFS(Calendar!$H$2:$H$426,Calendar!$A$2:$A$426,$A11,Calendar!$E$2:$E$426,"Swim") -> 6.1 | M11: =SUMIFS(Calendar!$H$2:$H$426,Calendar!$A$2:$A$426,$A11,Calendar!$E$2:$E$426,"Run") -> 15 | N11: — | O11: — | P11: =IFERROR(SUMIFS(Calendar!$M$2:$M$426,Calendar!$A$2:$A$426,$A11)/((SUMIFS(Calendar!$G$2:$G$426,Calendar!$A$2:$A$426,$A11,Calendar!$E$2:$E$426,"Swim"))+(SUMIFS(Calendar!$G$2:$G$426,Calendar!$A$2:$A$426,$A11,Calendar!$E$2:$E$426,"Bike"))+(SUMIFS(Calendar!$G$2:$G$426,Calendar!$A$2:$A$426,$A11,Calendar!$E$2:$E$426,"Run"))),0) -> 0.044186047
A12: 11 | B12: 46377 | C12: Base 3 | D12: load | E12: Christmas week — Fri is optional/easy. Threshold work begins on the bike. | F12: =SUMIFS(Calendar!$G$2:$G$426,Calendar!$A$2:$A$426,$A12)/60 -> 11.55 | G12: =SUMIFS(Calendar!$G$2:$G$426,Calendar!$A$2:$A$426,$A12,Calendar!$E$2:$E$426,"Swim")/60 -> 2.75 | H12: =SUMIFS(Calendar!$G$2:$G$426,Calendar!$A$2:$A$426,$A12,Calendar!$E$2:$E$426,"Bike")/60 -> 5.4166667 | I12: =SUMIFS(Calendar!$G$2:$G$426,Calendar!$A$2:$A$426,$A12,Calendar!$E$2:$E$426,"Run")/60 -> 1.9666667 | J12: =SUMIFS(Calendar!$G$2:$G$426,Calendar!$A$2:$A$426,$A12,Calendar!$E$2:$E$426,"Strength")/60 -> 1.4166667 | K12: =SUMIFS(Calendar!$G$2:$G$426,Calendar!$A$2:$A$426,$A12,Calendar!$E$2:$E$426,"Race")/60 -> 0 | L12: =SUMIFS(Calendar!$H$2:$H$426,Calendar!$A$2:$A$426,$A12,Calendar!$E$2:$E$426,"Swim") -> 8 | M12: =SUMIFS(Calendar!$H$2:$H$426,Calendar!$A$2:$A$426,$A12,Calendar!$E$2:$E$426,"Run") -> 19.7 | N12: =F12/F10-1 -> -0.0375 | O12: =M12/M10-1 -> 0.070652174 | P12: =IFERROR(SUMIFS(Calendar!$M$2:$M$426,Calendar!$A$2:$A$426,$A12)/((SUMIFS(Calendar!$G$2:$G$426,Calendar!$A$2:$A$426,$A12,Calendar!$E$2:$E$426,"Swim"))+(SUMIFS(Calendar!$G$2:$G$426,Calendar!$A$2:$A$426,$A12,Calendar!$E$2:$E$426,"Bike"))+(SUMIFS(Calendar!$G$2:$G$426,Calendar!$A$2:$A$426,$A12,Calendar!$E$2:$E$426,"Run"))),0) -> 0.10361842
A13: 12 | B13: 46384 | C13: Base 3 | D13: load | E13: Strides added. Long ride 3h15. | F13: =SUMIFS(Calendar!$G$2:$G$426,Calendar!$A$2:$A$426,$A13)/60 -> 12.566667 | G13: =SUMIFS(Calendar!$G$2:$G$426,Calendar!$A$2:$A$426,$A13,Calendar!$E$2:$E$426,"Swim")/60 -> 3 | H13: =SUMIFS(Calendar!$G$2:$G$426,Calendar!$A$2:$A$426,$A13,Calendar!$E$2:$E$426,"Bike")/60 -> 6 | I13: =SUMIFS(Calendar!$G$2:$G$426,Calendar!$A$2:$A$426,$A13,Calendar!$E$2:$E$426,"Run")/60 -> 2.15 | J13: =SUMIFS(Calendar!$G$2:$G$426,Calendar!$A$2:$A$426,$A13,Calendar!$E$2:$E$426,"Strength")/60 -> 1.4166667 | K13: =SUMIFS(Calendar!$G$2:$G$426,Calendar!$A$2:$A$426,$A13,Calendar!$E$2:$E$426,"Race")/60 -> 0 | L13: =SUMIFS(Calendar!$H$2:$H$426,Calendar!$A$2:$A$426,$A13,Calendar!$E$2:$E$426,"Swim") -> 8.8 | M13: =SUMIFS(Calendar!$H$2:$H$426,Calendar!$A$2:$A$426,$A13,Calendar!$E$2:$E$426,"Run") -> 21.5 | N13: =F13/F12-1 -> 0.088023088 | O13: =M13/M12-1 -> 0.091370558 | P13: =IFERROR(SUMIFS(Calendar!$M$2:$M$426,Calendar!$A$2:$A$426,$A13)/((SUMIFS(Calendar!$G$2:$G$426,Calendar!$A$2:$A$426,$A13,Calendar!$E$2:$E$426,"Swim"))+(SUMIFS(Calendar!$G$2:$G$426,Calendar!$A$2:$A$426,$A13,Calendar!$E$2:$E$426,"Bike"))+(SUMIFS(Calendar!$G$2:$G$426,Calendar!$A$2:$A$426,$A13,Calendar!$E$2:$E$426,"Run"))),0) -> 0.10014948
A14: 13 | B14: 46391 | C14: Base 3 | D14: load | E14: Biggest base week. | F14: =SUMIFS(Calendar!$G$2:$G$426,Calendar!$A$2:$A$426,$A14)/60 -> 13.416667 | G14: =SUMIFS(Calendar!$G$2:$G$426,Calendar!$A$2:$A$426,$A14,Calendar!$E$2:$E$426,"Swim")/60 -> 3.1666667 | H14: =SUMIFS(Calendar!$G$2:$G$426,Calendar!$A$2:$A$426,$A14,Calendar!$E$2:$E$426,"Bike")/60 -> 6.5 | I14: =SUMIFS(Calendar!$G$2:$G$426,Calendar!$A$2:$A$426,$A14,Calendar!$E$2:$E$426,"Run")/60 -> 2.3333333 | J14: =SUMIFS(Calendar!$G$2:$G$426,Calendar!$A$2:$A$426,$A14,Calendar!$E$2:$E$426,"Strength")/60 -> 1.4166667 | K14: =SUMIFS(Calendar!$G$2:$G$426,Calendar!$A$2:$A$426,$A14,Calendar!$E$2:$E$426,"Race")/60 -> 0 | L14: =SUMIFS(Calendar!$H$2:$H$426,Calendar!$A$2:$A$426,$A14,Calendar!$E$2:$E$426,"Swim") -> 9.3 | M14: =SUMIFS(Calendar!$H$2:$H$426,Calendar!$A$2:$A$426,$A14,Calendar!$E$2:$E$426,"Run") -> 23.3 | N14: =F14/F13-1 -> 0.067639257 | O14: =M14/M13-1 -> 0.08372093 | P14: =IFERROR(SUMIFS(Calendar!$M$2:$M$426,Calendar!$A$2:$A$426,$A14)/((SUMIFS(Calendar!$G$2:$G$426,Calendar!$A$2:$A$426,$A14,Calendar!$E$2:$E$426,"Swim"))+(SUMIFS(Calendar!$G$2:$G$426,Calendar!$A$2:$A$426,$A14,Calendar!$E$2:$E$426,"Bike"))+(SUMIFS(Calendar!$G$2:$G$426,Calendar!$A$2:$A$426,$A14,Calendar!$E$2:$E$426,"Run"))),0) -> 0.10416667
A15: 14 | B15: 46398 | C15: Base 3 | D15: recovery | E15: Recovery + tests. CHECKPOINT: tibia symptom-free on all runs since wk 8? If yes → London stays on & run intensity unlocks from wk 16. If not → see a sports doctor; drop London to the Olympic/T100 plan only. | F15: =SUMIFS(Calendar!$G$2:$G$426,Calendar!$A$2:$A$426,$A15)/60 -> 9.25 | G15: =SUMIFS(Calendar!$G$2:$G$426,Calendar!$A$2:$A$426,$A15,Calendar!$E$2:$E$426,"Swim")/60 -> 2.1666667 | H15: =SUMIFS(Calendar!$G$2:$G$426,Calendar!$A$2:$A$426,$A15,Calendar!$E$2:$E$426,"Bike")/60 -> 4.25 | I15: =SUMIFS(Calendar!$G$2:$G$426,Calendar!$A$2:$A$426,$A15,Calendar!$E$2:$E$426,"Run")/60 -> 1.8333333 | J15: =SUMIFS(Calendar!$G$2:$G$426,Calendar!$A$2:$A$426,$A15,Calendar!$E$2:$E$426,"Strength")/60 -> 1 | K15: =SUMIFS(Calendar!$G$2:$G$426,Calendar!$A$2:$A$426,$A15,Calendar!$E$2:$E$426,"Race")/60 -> 0 | L15: =SUMIFS(Calendar!$H$2:$H$426,Calendar!$A$2:$A$426,$A15,Calendar!$E$2:$E$426,"Swim") -> 5.8 | M15: =SUMIFS(Calendar!$H$2:$H$426,Calendar!$A$2:$A$426,$A15,Calendar!$E$2:$E$426,"Run") -> 18.3 | N15: — | O15: — | P15: =IFERROR(SUMIFS(Calendar!$M$2:$M$426,Calendar!$A$2:$A$426,$A15)/((SUMIFS(Calendar!$G$2:$G$426,Calendar!$A$2:$A$426,$A15,Calendar!$E$2:$E$426,"Swim"))+(SUMIFS(Calendar!$G$2:$G$426,Calendar!$A$2:$A$426,$A15,Calendar!$E$2:$E$426,"Bike"))+(SUMIFS(Calendar!$G$2:$G$426,Calendar!$A$2:$A$426,$A15,Calendar!$E$2:$E$426,"Run"))),0) -> 0.04040404
A16: 15 | B16: 46405 | C16: Build 1 | D16: load | E16: Build begins: threshold bike, IM-power blocks on long rides, open water from wk 17. | F16: =SUMIFS(Calendar!$G$2:$G$426,Calendar!$A$2:$A$426,$A16)/60 -> 13.616667 | G16: =SUMIFS(Calendar!$G$2:$G$426,Calendar!$A$2:$A$426,$A16,Calendar!$E$2:$E$426,"Swim")/60 -> 3.0833333 | H16: =SUMIFS(Calendar!$G$2:$G$426,Calendar!$A$2:$A$426,$A16,Calendar!$E$2:$E$426,"Bike")/60 -> 6.8333333 | I16: =SUMIFS(Calendar!$G$2:$G$426,Calendar!$A$2:$A$426,$A16,Calendar!$E$2:$E$426,"Run")/60 -> 2.5333333 | J16: =SUMIFS(Calendar!$G$2:$G$426,Calendar!$A$2:$A$426,$A16,Calendar!$E$2:$E$426,"Strength")/60 -> 1.1666667 | K16: =SUMIFS(Calendar!$G$2:$G$426,Calendar!$A$2:$A$426,$A16,Calendar!$E$2:$E$426,"Race")/60 -> 0 | L16: =SUMIFS(Calendar!$H$2:$H$426,Calendar!$A$2:$A$426,$A16,Calendar!$E$2:$E$426,"Swim") -> 9 | M16: =SUMIFS(Calendar!$H$2:$H$426,Calendar!$A$2:$A$426,$A16,Calendar!$E$2:$E$426,"Run") -> 25.3 | N16: =F16/F14-1 -> 0.014906832 | O16: =M16/M14-1 -> 0.08583691 | P16: =IFERROR(SUMIFS(Calendar!$M$2:$M$426,Calendar!$A$2:$A$426,$A16)/((SUMIFS(Calendar!$G$2:$G$426,Calendar!$A$2:$A$426,$A16,Calendar!$E$2:$E$426,"Swim"))+(SUMIFS(Calendar!$G$2:$G$426,Calendar!$A$2:$A$426,$A16,Calendar!$E$2:$E$426,"Bike"))+(SUMIFS(Calendar!$G$2:$G$426,Calendar!$A$2:$A$426,$A16,Calendar!$E$2:$E$426,"Run"))),0) -> 0.10174029
A17: 16 | B17: 46412 | C17: Build 1 | D17: load | E17: First run quality (cruise intervals) — only if wk 14 checkpoint passed. | F17: =SUMIFS(Calendar!$G$2:$G$426,Calendar!$A$2:$A$426,$A17)/60 -> 14.216667 | G17: =SUMIFS(Calendar!$G$2:$G$426,Calendar!$A$2:$A$426,$A17,Calendar!$E$2:$E$426,"Swim")/60 -> 3.1666667 | H17: =SUMIFS(Calendar!$G$2:$G$426,Calendar!$A$2:$A$426,$A17,Calendar!$E$2:$E$426,"Bike")/60 -> 7.1666667 | I17: =SUMIFS(Calendar!$G$2:$G$426,Calendar!$A$2:$A$426,$A17,Calendar!$E$2:$E$426,"Run")/60 -> 2.7166667 | J17: =SUMIFS(Calendar!$G$2:$G$426,Calendar!$A$2:$A$426,$A17,Calendar!$E$2:$E$426,"Strength")/60 -> 1.1666667 | K17: =SUMIFS(Calendar!$G$2:$G$426,Calendar!$A$2:$A$426,$A17,Calendar!$E$2:$E$426,"Race")/60 -> 0 | L17: =SUMIFS(Calendar!$H$2:$H$426,Calendar!$A$2:$A$426,$A17,Calendar!$E$2:$E$426,"Swim") -> 9.3 | M17: =SUMIFS(Calendar!$H$2:$H$426,Calendar!$A$2:$A$426,$A17,Calendar!$E$2:$E$426,"Run") -> 27.2 | N17: =F17/F16-1 -> 0.044063647 | O17: =M17/M16-1 -> 0.075098814 | P17: =IFERROR(SUMIFS(Calendar!$M$2:$M$426,Calendar!$A$2:$A$426,$A17)/((SUMIFS(Calendar!$G$2:$G$426,Calendar!$A$2:$A$426,$A17,Calendar!$E$2:$E$426,"Swim"))+(SUMIFS(Calendar!$G$2:$G$426,Calendar!$A$2:$A$426,$A17,Calendar!$E$2:$E$426,"Bike"))+(SUMIFS(Calendar!$G$2:$G$426,Calendar!$A$2:$A$426,$A17,Calendar!$E$2:$E$426,"Run"))),0) -> 0.11621967
A18: 17 | B18: 46419 | C18: Build 1 | D18: load | E18: Open-water swims start Sundays. Get the wetsuit before this week. | F18: =SUMIFS(Calendar!$G$2:$G$426,Calendar!$A$2:$A$426,$A18)/60 -> 14.65 | G18: =SUMIFS(Calendar!$G$2:$G$426,Calendar!$A$2:$A$426,$A18,Calendar!$E$2:$E$426,"Swim")/60 -> 2.9166667 | H18: =SUMIFS(Calendar!$G$2:$G$426,Calendar!$A$2:$A$426,$A18,Calendar!$E$2:$E$426,"Bike")/60 -> 7.6666667 | I18: =SUMIFS(Calendar!$G$2:$G$426,Calendar!$A$2:$A$426,$A18,Calendar!$E$2:$E$426,"Run")/60 -> 2.9 | J18: =SUMIFS(Calendar!$G$2:$G$426,Calendar!$A$2:$A$426,$A18,Calendar!$E$2:$E$426,"Strength")/60 -> 1.1666667 | K18: =SUMIFS(Calendar!$G$2:$G$426,Calendar!$A$2:$A$426,$A18,Calendar!$E$2:$E$426,"Race")/60 -> 0 | L18: =SUMIFS(Calendar!$H$2:$H$426,Calendar!$A$2:$A$426,$A18,Calendar!$E$2:$E$426,"Swim") -> 8.4 | M18: =SUMIFS(Calendar!$H$2:$H$426,Calendar!$A$2:$A$426,$A18,Calendar!$E$2:$E$426,"Run") -> 29 | N18: =F18/F17-1 -> 0.030480657 | O18: =M18/M17-1 -> 0.066176471 | P18: =IFERROR(SUMIFS(Calendar!$M$2:$M$426,Calendar!$A$2:$A$426,$A18)/((SUMIFS(Calendar!$G$2:$G$426,Calendar!$A$2:$A$426,$A18,Calendar!$E$2:$E$426,"Swim"))+(SUMIFS(Calendar!$G$2:$G$426,Calendar!$A$2:$A$426,$A18,Calendar!$E$2:$E$426,"Bike"))+(SUMIFS(Calendar!$G$2:$G$426,Calendar!$A$2:$A$426,$A18,Calendar!$E$2:$E$426,"Run"))),0) -> 0.12855377
A19: 18 | B19: 46426 | C19: Build 1 | D19: recovery | E19: Recovery + CSS retest. | F19: =SUMIFS(Calendar!$G$2:$G$426,Calendar!$A$2:$A$426,$A19)/60 -> 10.833333 | G19: =SUMIFS(Calendar!$G$2:$G$426,Calendar!$A$2:$A$426,$A19,Calendar!$E$2:$E$426,"Swim")/60 -> 2 | H19: =SUMIFS(Calendar!$G$2:$G$426,Calendar!$A$2:$A$426,$A19,Calendar!$E$2:$E$426,"Bike")/60 -> 5.5 | I19: =SUMIFS(Calendar!$G$2:$G$426,Calendar!$A$2:$A$426,$A19,Calendar!$E$2:$E$426,"Run")/60 -> 2.4166667 | J19: =SUMIFS(Calendar!$G$2:$G$426,Calendar!$A$2:$A$426,$A19,Calendar!$E$2:$E$426,"Strength")/60 -> 0.91666667 | K19: =SUMIFS(Calendar!$G$2:$G$426,Calendar!$A$2:$A$426,$A19,Calendar!$E$2:$E$426,"Race")/60 -> 0 | L19: =SUMIFS(Calendar!$H$2:$H$426,Calendar!$A$2:$A$426,$A19,Calendar!$E$2:$E$426,"Swim") -> 5.2 | M19: =SUMIFS(Calendar!$H$2:$H$426,Calendar!$A$2:$A$426,$A19,Calendar!$E$2:$E$426,"Run") -> 24.1 | N19: — | O19: — | P19: =IFERROR(SUMIFS(Calendar!$M$2:$M$426,Calendar!$A$2:$A$426,$A19)/((SUMIFS(Calendar!$G$2:$G$426,Calendar!$A$2:$A$426,$A19,Calendar!$E$2:$E$426,"Swim"))+(SUMIFS(Calendar!$G$2:$G$426,Calendar!$A$2:$A$426,$A19,Calendar!$E$2:$E$426,"Bike"))+(SUMIFS(Calendar!$G$2:$G$426,Calendar!$A$2:$A$426,$A19,Calendar!$E$2:$E$426,"Run"))),0) -> 0.025210084
A20: 19 | B20: 46433 | C20: Build 2 | D20: load | E20: Optional: a local sprint tri on Sun 21 Feb for transition practice (swap for Sun long run). | F20: =SUMIFS(Calendar!$G$2:$G$426,Calendar!$A$2:$A$426,$A20)/60 -> 15.1 | G20: =SUMIFS(Calendar!$G$2:$G$426,Calendar!$A$2:$A$426,$A20,Calendar!$E$2:$E$426,"Swim")/60 -> 2.9166667 | H20: =SUMIFS(Calendar!$G$2:$G$426,Calendar!$A$2:$A$426,$A20,Calendar!$E$2:$E$426,"Bike")/60 -> 7.9166667 | I20: =SUMIFS(Calendar!$G$2:$G$426,Calendar!$A$2:$A$426,$A20,Calendar!$E$2:$E$426,"Run")/60 -> 3.1 | J20: =SUMIFS(Calendar!$G$2:$G$426,Calendar!$A$2:$A$426,$A20,Calendar!$E$2:$E$426,"Strength")/60 -> 1.1666667 | K20: =SUMIFS(Calendar!$G$2:$G$426,Calendar!$A$2:$A$426,$A20,Calendar!$E$2:$E$426,"Race")/60 -> 0 | L20: =SUMIFS(Calendar!$H$2:$H$426,Calendar!$A$2:$A$426,$A20,Calendar!$E$2:$E$426,"Swim") -> 8.4 | M20: =SUMIFS(Calendar!$H$2:$H$426,Calendar!$A$2:$A$426,$A20,Calendar!$E$2:$E$426,"Run") -> 31 | N20: =F20/F18-1 -> 0.030716724 | O20: =M20/M18-1 -> 0.068965517 | P20: =IFERROR(SUMIFS(Calendar!$M$2:$M$426,Calendar!$A$2:$A$426,$A20)/((SUMIFS(Calendar!$G$2:$G$426,Calendar!$A$2:$A$426,$A20,Calendar!$E$2:$E$426,"Swim"))+(SUMIFS(Calendar!$G$2:$G$426,Calendar!$A$2:$A$426,$A20,Calendar!$E$2:$E$426,"Bike"))+(SUMIFS(Calendar!$G$2:$G$426,Calendar!$A$2:$A$426,$A20,Calendar!$E$2:$E$426,"Run"))),0) -> 0.10526316
A21: 20 | B21: 46440 | C21: Build 2 | D21: load | E21: Long ride 5h. | F21: =SUMIFS(Calendar!$G$2:$G$426,Calendar!$A$2:$A$426,$A21)/60 -> 16.033333 | G21: =SUMIFS(Calendar!$G$2:$G$426,Calendar!$A$2:$A$426,$A21,Calendar!$E$2:$E$426,"Swim")/60 -> 3.1666667 | H21: =SUMIFS(Calendar!$G$2:$G$426,Calendar!$A$2:$A$426,$A21,Calendar!$E$2:$E$426,"Bike")/60 -> 8.3333333 | I21: =SUMIFS(Calendar!$G$2:$G$426,Calendar!$A$2:$A$426,$A21,Calendar!$E$2:$E$426,"Run")/60 -> 3.3666667 | J21: =SUMIFS(Calendar!$G$2:$G$426,Calendar!$A$2:$A$426,$A21,Calendar!$E$2:$E$426,"Strength")/60 -> 1.1666667 | K21: =SUMIFS(Calendar!$G$2:$G$426,Calendar!$A$2:$A$426,$A21,Calendar!$E$2:$E$426,"Race")/60 -> 0 | L21: =SUMIFS(Calendar!$H$2:$H$426,Calendar!$A$2:$A$426,$A21,Calendar!$E$2:$E$426,"Swim") -> 9.1 | M21: =SUMIFS(Calendar!$H$2:$H$426,Calendar!$A$2:$A$426,$A21,Calendar!$E$2:$E$426,"Run") -> 33.6 | N21: =F21/F20-1 -> 0.061810155 | O21: =M21/M20-1 -> 0.083870968 | P21: =IFERROR(SUMIFS(Calendar!$M$2:$M$426,Calendar!$A$2:$A$426,$A21)/((SUMIFS(Calendar!$G$2:$G$426,Calendar!$A$2:$A$426,$A21,Calendar!$E$2:$E$426,"Swim"))+(SUMIFS(Calendar!$G$2:$G$426,Calendar!$A$2:$A$426,$A21,Calendar!$E$2:$E$426,"Bike"))+(SUMIFS(Calendar!$G$2:$G$426,Calendar!$A$2:$A$426,$A21,Calendar!$E$2:$E$426,"Run"))),0) -> 0.10650224
A22: 21 | B22: 46447 | C22: Build 2 | D22: load | E22: Peak build week before T100. | F22: =SUMIFS(Calendar!$G$2:$G$426,Calendar!$A$2:$A$426,$A22)/60 -> 16.666667 | G22: =SUMIFS(Calendar!$G$2:$G$426,Calendar!$A$2:$A$426,$A22,Calendar!$E$2:$E$426,"Swim")/60 -> 3.1666667 | H22: =SUMIFS(Calendar!$G$2:$G$426,Calendar!$A$2:$A$426,$A22,Calendar!$E$2:$E$426,"Bike")/60 -> 8.6666667 | I22: =SUMIFS(Calendar!$G$2:$G$426,Calendar!$A$2:$A$426,$A22,Calendar!$E$2:$E$426,"Run")/60 -> 3.6666667 | J22: =SUMIFS(Calendar!$G$2:$G$426,Calendar!$A$2:$A$426,$A22,Calendar!$E$2:$E$426,"Strength")/60 -> 1.1666667 | K22: =SUMIFS(Calendar!$G$2:$G$426,Calendar!$A$2:$A$426,$A22,Calendar!$E$2:$E$426,"Race")/60 -> 0 | L22: =SUMIFS(Calendar!$H$2:$H$426,Calendar!$A$2:$A$426,$A22,Calendar!$E$2:$E$426,"Swim") -> 9.1 | M22: =SUMIFS(Calendar!$H$2:$H$426,Calendar!$A$2:$A$426,$A22,Calendar!$E$2:$E$426,"Run") -> 36.7 | N22: =F22/F21-1 -> 0.03950104 | O22: =M22/M21-1 -> 0.092261905 | P22: =IFERROR(SUMIFS(Calendar!$M$2:$M$426,Calendar!$A$2:$A$426,$A22)/((SUMIFS(Calendar!$G$2:$G$426,Calendar!$A$2:$A$426,$A22,Calendar!$E$2:$E$426,"Swim"))+(SUMIFS(Calendar!$G$2:$G$426,Calendar!$A$2:$A$426,$A22,Calendar!$E$2:$E$426,"Bike"))+(SUMIFS(Calendar!$G$2:$G$426,Calendar!$A$2:$A$426,$A22,Calendar!$E$2:$E$426,"Run"))),0) -> 0.1172043
A23: 22 | B23: 46454 | C23: Build 2 | D23: recovery | E23: Recovery + FTP retest. Set T100 race targets from new FTP. | F23: =SUMIFS(Calendar!$G$2:$G$426,Calendar!$A$2:$A$426,$A23)/60 -> 12.083333 | G23: =SUMIFS(Calendar!$G$2:$G$426,Calendar!$A$2:$A$426,$A23,Calendar!$E$2:$E$426,"Swim")/60 -> 2.3333333 | H23: =SUMIFS(Calendar!$G$2:$G$426,Calendar!$A$2:$A$426,$A23,Calendar!$E$2:$E$426,"Bike")/60 -> 5.5 | I23: =SUMIFS(Calendar!$G$2:$G$426,Calendar!$A$2:$A$426,$A23,Calendar!$E$2:$E$426,"Run")/60 -> 3.3333333 | J23: =SUMIFS(Calendar!$G$2:$G$426,Calendar!$A$2:$A$426,$A23,Calendar!$E$2:$E$426,"Strength")/60 -> 0.91666667 | K23: =SUMIFS(Calendar!$G$2:$G$426,Calendar!$A$2:$A$426,$A23,Calendar!$E$2:$E$426,"Race")/60 -> 0 | L23: =SUMIFS(Calendar!$H$2:$H$426,Calendar!$A$2:$A$426,$A23,Calendar!$E$2:$E$426,"Swim") -> 6.4 | M23: =SUMIFS(Calendar!$H$2:$H$426,Calendar!$A$2:$A$426,$A23,Calendar!$E$2:$E$426,"Run") -> 33.2 | N23: — | O23: — | P23: =IFERROR(SUMIFS(Calendar!$M$2:$M$426,Calendar!$A$2:$A$426,$A23)/((SUMIFS(Calendar!$G$2:$G$426,Calendar!$A$2:$A$426,$A23,Calendar!$E$2:$E$426,"Swim"))+(SUMIFS(Calendar!$G$2:$G$426,Calendar!$A$2:$A$426,$A23,Calendar!$E$2:$E$426,"Bike"))+(SUMIFS(Calendar!$G$2:$G$426,Calendar!$A$2:$A$426,$A23,Calendar!$E$2:$E$426,"Run"))),0) -> 0.059701493
A24: 23 | B24: 46461 | C24: Race: T100 | D24: race | E24: Gold Coast T100 (2km/80km/18km) Sun 21 Mar — controlled IM-rehearsal effort, not all-out (London in 5 weeks). | F24: =SUMIFS(Calendar!$G$2:$G$426,Calendar!$A$2:$A$426,$A24)/60 -> 11 | G24: =SUMIFS(Calendar!$G$2:$G$426,Calendar!$A$2:$A$426,$A24,Calendar!$E$2:$E$426,"Swim")/60 -> 2.0833333 | H24: =SUMIFS(Calendar!$G$2:$G$426,Calendar!$A$2:$A$426,$A24,Calendar!$E$2:$E$426,"Bike")/60 -> 2.3333333 | I24: =SUMIFS(Calendar!$G$2:$G$426,Calendar!$A$2:$A$426,$A24,Calendar!$E$2:$E$426,"Run")/60 -> 1.1666667 | J24: =SUMIFS(Calendar!$G$2:$G$426,Calendar!$A$2:$A$426,$A24,Calendar!$E$2:$E$426,"Strength")/60 -> 0.41666667 | K24: =SUMIFS(Calendar!$G$2:$G$426,Calendar!$A$2:$A$426,$A24,Calendar!$E$2:$E$426,"Race")/60 -> 5 | L24: =SUMIFS(Calendar!$H$2:$H$426,Calendar!$A$2:$A$426,$A24,Calendar!$E$2:$E$426,"Swim") -> 6 | M24: =SUMIFS(Calendar!$H$2:$H$426,Calendar!$A$2:$A$426,$A24,Calendar!$E$2:$E$426,"Run") -> 11.7 | N24: — | O24: — | P24: =IFERROR(SUMIFS(Calendar!$M$2:$M$426,Calendar!$A$2:$A$426,$A24)/((SUMIFS(Calendar!$G$2:$G$426,Calendar!$A$2:$A$426,$A24,Calendar!$E$2:$E$426,"Swim"))+(SUMIFS(Calendar!$G$2:$G$426,Calendar!$A$2:$A$426,$A24,Calendar!$E$2:$E$426,"Bike"))+(SUMIFS(Calendar!$G$2:$G$426,Calendar!$A$2:$A$426,$A24,Calendar!$E$2:$E$426,"Run"))),0) -> 0.35522388
A25: 24 | B25: 46468 | C25: Build 3 | D25: recovery | E25: Post-race recovery; rebuild by Saturday. | F25: =SUMIFS(Calendar!$G$2:$G$426,Calendar!$A$2:$A$426,$A25)/60 -> 10.583333 | G25: =SUMIFS(Calendar!$G$2:$G$426,Calendar!$A$2:$A$426,$A25,Calendar!$E$2:$E$426,"Swim")/60 -> 2.4166667 | H25: =SUMIFS(Calendar!$G$2:$G$426,Calendar!$A$2:$A$426,$A25,Calendar!$E$2:$E$426,"Bike")/60 -> 4.75 | I25: =SUMIFS(Calendar!$G$2:$G$426,Calendar!$A$2:$A$426,$A25,Calendar!$E$2:$E$426,"Run")/60 -> 2.5 | J25: =SUMIFS(Calendar!$G$2:$G$426,Calendar!$A$2:$A$426,$A25,Calendar!$E$2:$E$426,"Strength")/60 -> 0.91666667 | K25: =SUMIFS(Calendar!$G$2:$G$426,Calendar!$A$2:$A$426,$A25,Calendar!$E$2:$E$426,"Race")/60 -> 0 | L25: =SUMIFS(Calendar!$H$2:$H$426,Calendar!$A$2:$A$426,$A25,Calendar!$E$2:$E$426,"Swim") -> 7.1 | M25: =SUMIFS(Calendar!$H$2:$H$426,Calendar!$A$2:$A$426,$A25,Calendar!$E$2:$E$426,"Run") -> 25 | N25: — | O25: — | P25: =IFERROR(SUMIFS(Calendar!$M$2:$M$426,Calendar!$A$2:$A$426,$A25)/((SUMIFS(Calendar!$G$2:$G$426,Calendar!$A$2:$A$426,$A25,Calendar!$E$2:$E$426,"Swim"))+(SUMIFS(Calendar!$G$2:$G$426,Calendar!$A$2:$A$426,$A25,Calendar!$E$2:$E$426,"Bike"))+(SUMIFS(Calendar!$G$2:$G$426,Calendar!$A$2:$A$426,$A25,Calendar!$E$2:$E$426,"Run"))),0) -> 0.0051724138
A26: 25 | B26: 46475 | C26: Build 3 | D26: load | E26: Big block: London long run + IM long ride. | F26: =SUMIFS(Calendar!$G$2:$G$426,Calendar!$A$2:$A$426,$A26)/60 -> 17.083333 | G26: =SUMIFS(Calendar!$G$2:$G$426,Calendar!$A$2:$A$426,$A26,Calendar!$E$2:$E$426,"Swim")/60 -> 3.0833333 | H26: =SUMIFS(Calendar!$G$2:$G$426,Calendar!$A$2:$A$426,$A26,Calendar!$E$2:$E$426,"Bike")/60 -> 8.8333333 | I26: =SUMIFS(Calendar!$G$2:$G$426,Calendar!$A$2:$A$426,$A26,Calendar!$E$2:$E$426,"Run")/60 -> 4 | J26: =SUMIFS(Calendar!$G$2:$G$426,Calendar!$A$2:$A$426,$A26,Calendar!$E$2:$E$426,"Strength")/60 -> 1.1666667 | K26: =SUMIFS(Calendar!$G$2:$G$426,Calendar!$A$2:$A$426,$A26,Calendar!$E$2:$E$426,"Race")/60 -> 0 | L26: =SUMIFS(Calendar!$H$2:$H$426,Calendar!$A$2:$A$426,$A26,Calendar!$E$2:$E$426,"Swim") -> 8.9 | M26: =SUMIFS(Calendar!$H$2:$H$426,Calendar!$A$2:$A$426,$A26,Calendar!$E$2:$E$426,"Run") -> 40.1 | N26: =F26/F22-1 -> 0.025 | O26: =M26/M22-1 -> 0.092643052 | P26: =IFERROR(SUMIFS(Calendar!$M$2:$M$426,Calendar!$A$2:$A$426,$A26)/((SUMIFS(Calendar!$G$2:$G$426,Calendar!$A$2:$A$426,$A26,Calendar!$E$2:$E$426,"Swim"))+(SUMIFS(Calendar!$G$2:$G$426,Calendar!$A$2:$A$426,$A26,Calendar!$E$2:$E$426,"Bike"))+(SUMIFS(Calendar!$G$2:$G$426,Calendar!$A$2:$A$426,$A26,Calendar!$E$2:$E$426,"Run"))),0) -> 0.10575916
A27: 26 | B27: 46482 | C27: Build 3 | D27: load | E27: Peak pre-London week: 6h ride + 27.5km long run (Z2). | F27: =SUMIFS(Calendar!$G$2:$G$426,Calendar!$A$2:$A$426,$A27)/60 -> 18.05 | G27: =SUMIFS(Calendar!$G$2:$G$426,Calendar!$A$2:$A$426,$A27,Calendar!$E$2:$E$426,"Swim")/60 -> 3.1666667 | H27: =SUMIFS(Calendar!$G$2:$G$426,Calendar!$A$2:$A$426,$A27,Calendar!$E$2:$E$426,"Bike")/60 -> 9.3333333 | I27: =SUMIFS(Calendar!$G$2:$G$426,Calendar!$A$2:$A$426,$A27,Calendar!$E$2:$E$426,"Run")/60 -> 4.3833333 | J27: =SUMIFS(Calendar!$G$2:$G$426,Calendar!$A$2:$A$426,$A27,Calendar!$E$2:$E$426,"Strength")/60 -> 1.1666667 | K27: =SUMIFS(Calendar!$G$2:$G$426,Calendar!$A$2:$A$426,$A27,Calendar!$E$2:$E$426,"Race")/60 -> 0 | L27: =SUMIFS(Calendar!$H$2:$H$426,Calendar!$A$2:$A$426,$A27,Calendar!$E$2:$E$426,"Swim") -> 9.1 | M27: =SUMIFS(Calendar!$H$2:$H$426,Calendar!$A$2:$A$426,$A27,Calendar!$E$2:$E$426,"Run") -> 43.9 | N27: =F27/F26-1 -> 0.056585366 | O27: =M27/M26-1 -> 0.094763092 | P27: =IFERROR(SUMIFS(Calendar!$M$2:$M$426,Calendar!$A$2:$A$426,$A27)/((SUMIFS(Calendar!$G$2:$G$426,Calendar!$A$2:$A$426,$A27,Calendar!$E$2:$E$426,"Swim"))+(SUMIFS(Calendar!$G$2:$G$426,Calendar!$A$2:$A$426,$A27,Calendar!$E$2:$E$426,"Bike"))+(SUMIFS(Calendar!$G$2:$G$426,Calendar!$A$2:$A$426,$A27,Calendar!$E$2:$E$426,"Run"))),0) -> 0.09970385
A28: 27 | B28: 46489 | C28: Build 3 | D28: reduced | E28: London mini-taper (run −30%); last long ride before the 19-day bike gap. | F28: =SUMIFS(Calendar!$G$2:$G$426,Calendar!$A$2:$A$426,$A28)/60 -> 14.433333 | G28: =SUMIFS(Calendar!$G$2:$G$426,Calendar!$A$2:$A$426,$A28,Calendar!$E$2:$E$426,"Swim")/60 -> 3 | H28: =SUMIFS(Calendar!$G$2:$G$426,Calendar!$A$2:$A$426,$A28,Calendar!$E$2:$E$426,"Bike")/60 -> 7 | I28: =SUMIFS(Calendar!$G$2:$G$426,Calendar!$A$2:$A$426,$A28,Calendar!$E$2:$E$426,"Run")/60 -> 3.5166667 | J28: =SUMIFS(Calendar!$G$2:$G$426,Calendar!$A$2:$A$426,$A28,Calendar!$E$2:$E$426,"Strength")/60 -> 0.91666667 | K28: =SUMIFS(Calendar!$G$2:$G$426,Calendar!$A$2:$A$426,$A28,Calendar!$E$2:$E$426,"Race")/60 -> 0 | L28: =SUMIFS(Calendar!$H$2:$H$426,Calendar!$A$2:$A$426,$A28,Calendar!$E$2:$E$426,"Swim") -> 8.8 | M28: =SUMIFS(Calendar!$H$2:$H$426,Calendar!$A$2:$A$426,$A28,Calendar!$E$2:$E$426,"Run") -> 35.2 | N28: — | O28: — | P28: =IFERROR(SUMIFS(Calendar!$M$2:$M$426,Calendar!$A$2:$A$426,$A28)/((SUMIFS(Calendar!$G$2:$G$426,Calendar!$A$2:$A$426,$A28,Calendar!$E$2:$E$426,"Swim"))+(SUMIFS(Calendar!$G$2:$G$426,Calendar!$A$2:$A$426,$A28,Calendar!$E$2:$E$426,"Bike"))+(SUMIFS(Calendar!$G$2:$G$426,Calendar!$A$2:$A$426,$A28,Calendar!$E$2:$E$426,"Run"))),0) -> 0.067817509
A29: 28 | B29: 46496 | C29: London | D29: race | E29: London Marathon Sun 25 Apr at Z2. Fly Wed 21 Apr (last ride Tue). | F29: =SUMIFS(Calendar!$G$2:$G$426,Calendar!$A$2:$A$426,$A29)/60 -> 8.3333333 | G29: =SUMIFS(Calendar!$G$2:$G$426,Calendar!$A$2:$A$426,$A29,Calendar!$E$2:$E$426,"Swim")/60 -> 1.1666667 | H29: =SUMIFS(Calendar!$G$2:$G$426,Calendar!$A$2:$A$426,$A29,Calendar!$E$2:$E$426,"Bike")/60 -> 1.75 | I29: =SUMIFS(Calendar!$G$2:$G$426,Calendar!$A$2:$A$426,$A29,Calendar!$E$2:$E$426,"Run")/60 -> 1.3333333 | J29: =SUMIFS(Calendar!$G$2:$G$426,Calendar!$A$2:$A$426,$A29,Calendar!$E$2:$E$426,"Strength")/60 -> 0 | K29: =SUMIFS(Calendar!$G$2:$G$426,Calendar!$A$2:$A$426,$A29,Calendar!$E$2:$E$426,"Race")/60 -> 4.0833333 | L29: =SUMIFS(Calendar!$H$2:$H$426,Calendar!$A$2:$A$426,$A29,Calendar!$E$2:$E$426,"Swim") -> 3.2 | M29: =SUMIFS(Calendar!$H$2:$H$426,Calendar!$A$2:$A$426,$A29,Calendar!$E$2:$E$426,"Run") -> 13.5 | N29: — | O29: — | P29: =IFERROR(SUMIFS(Calendar!$M$2:$M$426,Calendar!$A$2:$A$426,$A29)/((SUMIFS(Calendar!$G$2:$G$426,Calendar!$A$2:$A$426,$A29,Calendar!$E$2:$E$426,"Swim"))+(SUMIFS(Calendar!$G$2:$G$426,Calendar!$A$2:$A$426,$A29,Calendar!$E$2:$E$426,"Bike"))+(SUMIFS(Calendar!$G$2:$G$426,Calendar!$A$2:$A$426,$A29,Calendar!$E$2:$E$426,"Run"))),0) -> 0.011764706
A30: 29 | B30: 46503 | C30: London | D30: recovery | E30: Post-marathon recovery in London. No running Mon–Fri; no road bike. | F30: =SUMIFS(Calendar!$G$2:$G$426,Calendar!$A$2:$A$426,$A30)/60 -> 4.1666667 | G30: =SUMIFS(Calendar!$G$2:$G$426,Calendar!$A$2:$A$426,$A30,Calendar!$E$2:$E$426,"Swim")/60 -> 2.0833333 | H30: =SUMIFS(Calendar!$G$2:$G$426,Calendar!$A$2:$A$426,$A30,Calendar!$E$2:$E$426,"Bike")/60 -> 1.1666667 | I30: =SUMIFS(Calendar!$G$2:$G$426,Calendar!$A$2:$A$426,$A30,Calendar!$E$2:$E$426,"Run")/60 -> 0.41666667 | J30: =SUMIFS(Calendar!$G$2:$G$426,Calendar!$A$2:$A$426,$A30,Calendar!$E$2:$E$426,"Strength")/60 -> 0.5 | K30: =SUMIFS(Calendar!$G$2:$G$426,Calendar!$A$2:$A$426,$A30,Calendar!$E$2:$E$426,"Race")/60 -> 0 | L30: =SUMIFS(Calendar!$H$2:$H$426,Calendar!$A$2:$A$426,$A30,Calendar!$E$2:$E$426,"Swim") -> 5.8 | M30: =SUMIFS(Calendar!$H$2:$H$426,Calendar!$A$2:$A$426,$A30,Calendar!$E$2:$E$426,"Run") -> 4 | N30: — | O30: — | P30: =IFERROR(SUMIFS(Calendar!$M$2:$M$426,Calendar!$A$2:$A$426,$A30)/((SUMIFS(Calendar!$G$2:$G$426,Calendar!$A$2:$A$426,$A30,Calendar!$E$2:$E$426,"Swim"))+(SUMIFS(Calendar!$G$2:$G$426,Calendar!$A$2:$A$426,$A30,Calendar!$E$2:$E$426,"Bike"))+(SUMIFS(Calendar!$G$2:$G$426,Calendar!$A$2:$A$426,$A30,Calendar!$E$2:$E$426,"Run"))),0) -> 0
A31: 30 | B31: 46510 | C31: London | D31: reduced | E31: Rebuild in London: swim, run, gym — gym bike / Wattbike if available (by HR). | F31: =SUMIFS(Calendar!$G$2:$G$426,Calendar!$A$2:$A$426,$A31)/60 -> 10.333333 | G31: =SUMIFS(Calendar!$G$2:$G$426,Calendar!$A$2:$A$426,$A31,Calendar!$E$2:$E$426,"Swim")/60 -> 2.8333333 | H31: =SUMIFS(Calendar!$G$2:$G$426,Calendar!$A$2:$A$426,$A31,Calendar!$E$2:$E$426,"Bike")/60 -> 3.25 | I31: =SUMIFS(Calendar!$G$2:$G$426,Calendar!$A$2:$A$426,$A31,Calendar!$E$2:$E$426,"Run")/60 -> 3.25 | J31: =SUMIFS(Calendar!$G$2:$G$426,Calendar!$A$2:$A$426,$A31,Calendar!$E$2:$E$426,"Strength")/60 -> 1 | K31: =SUMIFS(Calendar!$G$2:$G$426,Calendar!$A$2:$A$426,$A31,Calendar!$E$2:$E$426,"Race")/60 -> 0 | L31: =SUMIFS(Calendar!$H$2:$H$426,Calendar!$A$2:$A$426,$A31,Calendar!$E$2:$E$426,"Swim") -> 8.4 | M31: =SUMIFS(Calendar!$H$2:$H$426,Calendar!$A$2:$A$426,$A31,Calendar!$E$2:$E$426,"Run") -> 32.4 | N31: — | O31: — | P31: =IFERROR(SUMIFS(Calendar!$M$2:$M$426,Calendar!$A$2:$A$426,$A31)/((SUMIFS(Calendar!$G$2:$G$426,Calendar!$A$2:$A$426,$A31,Calendar!$E$2:$E$426,"Swim"))+(SUMIFS(Calendar!$G$2:$G$426,Calendar!$A$2:$A$426,$A31,Calendar!$E$2:$E$426,"Bike"))+(SUMIFS(Calendar!$G$2:$G$426,Calendar!$A$2:$A$426,$A31,Calendar!$E$2:$E$426,"Run"))),0) -> 0.05
A32: 31 | B32: 46517 | C32: Peak | D32: load | E32: Back on the bike — IM-specific block. Heat acclimation starts (Thu). | F32: =SUMIFS(Calendar!$G$2:$G$426,Calendar!$A$2:$A$426,$A32)/60 -> 16.25 | G32: =SUMIFS(Calendar!$G$2:$G$426,Calendar!$A$2:$A$426,$A32,Calendar!$E$2:$E$426,"Swim")/60 -> 3 | H32: =SUMIFS(Calendar!$G$2:$G$426,Calendar!$A$2:$A$426,$A32,Calendar!$E$2:$E$426,"Bike")/60 -> 7.75 | I32: =SUMIFS(Calendar!$G$2:$G$426,Calendar!$A$2:$A$426,$A32,Calendar!$E$2:$E$426,"Run")/60 -> 4.5833333 | J32: =SUMIFS(Calendar!$G$2:$G$426,Calendar!$A$2:$A$426,$A32,Calendar!$E$2:$E$426,"Strength")/60 -> 0.91666667 | K32: =SUMIFS(Calendar!$G$2:$G$426,Calendar!$A$2:$A$426,$A32,Calendar!$E$2:$E$426,"Race")/60 -> 0 | L32: =SUMIFS(Calendar!$H$2:$H$426,Calendar!$A$2:$A$426,$A32,Calendar!$E$2:$E$426,"Swim") -> 8.7 | M32: =SUMIFS(Calendar!$H$2:$H$426,Calendar!$A$2:$A$426,$A32,Calendar!$E$2:$E$426,"Run") -> 45.9 | N32: =F32/F27-1 -> -0.099722992 | O32: =M32/M27-1 -> 0.045558087 | P32: =IFERROR(SUMIFS(Calendar!$M$2:$M$426,Calendar!$A$2:$A$426,$A32)/((SUMIFS(Calendar!$G$2:$G$426,Calendar!$A$2:$A$426,$A32,Calendar!$E$2:$E$426,"Swim"))+(SUMIFS(Calendar!$G$2:$G$426,Calendar!$A$2:$A$426,$A32,Calendar!$E$2:$E$426,"Bike"))+(SUMIFS(Calendar!$G$2:$G$426,Calendar!$A$2:$A$426,$A32,Calendar!$E$2:$E$426,"Run"))),0) -> 0.069565217
A33: 32 | B33: 46524 | C33: Peak | D33: load | E33: Biggest IM-specific week: 5h15 ride (3.5h @ IM power) + 45' brick; 3.8km continuous swim. | F33: =SUMIFS(Calendar!$G$2:$G$426,Calendar!$A$2:$A$426,$A33)/60 -> 17.583333 | G33: =SUMIFS(Calendar!$G$2:$G$426,Calendar!$A$2:$A$426,$A33,Calendar!$E$2:$E$426,"Swim")/60 -> 3.4166667 | H33: =SUMIFS(Calendar!$G$2:$G$426,Calendar!$A$2:$A$426,$A33,Calendar!$E$2:$E$426,"Bike")/60 -> 8.5 | I33: =SUMIFS(Calendar!$G$2:$G$426,Calendar!$A$2:$A$426,$A33,Calendar!$E$2:$E$426,"Run")/60 -> 4.8333333 | J33: =SUMIFS(Calendar!$G$2:$G$426,Calendar!$A$2:$A$426,$A33,Calendar!$E$2:$E$426,"Strength")/60 -> 0.83333333 | K33: =SUMIFS(Calendar!$G$2:$G$426,Calendar!$A$2:$A$426,$A33,Calendar!$E$2:$E$426,"Race")/60 -> 0 | L33: =SUMIFS(Calendar!$H$2:$H$426,Calendar!$A$2:$A$426,$A33,Calendar!$E$2:$E$426,"Swim") -> 9.5 | M33: =SUMIFS(Calendar!$H$2:$H$426,Calendar!$A$2:$A$426,$A33,Calendar!$E$2:$E$426,"Run") -> 48.4 | N33: =F33/F32-1 -> 0.082051282 | O33: =M33/M32-1 -> 0.054466231 | P33: =IFERROR(SUMIFS(Calendar!$M$2:$M$426,Calendar!$A$2:$A$426,$A33)/((SUMIFS(Calendar!$G$2:$G$426,Calendar!$A$2:$A$426,$A33,Calendar!$E$2:$E$426,"Swim"))+(SUMIFS(Calendar!$G$2:$G$426,Calendar!$A$2:$A$426,$A33,Calendar!$E$2:$E$426,"Bike"))+(SUMIFS(Calendar!$G$2:$G$426,Calendar!$A$2:$A$426,$A33,Calendar!$E$2:$E$426,"Run"))),0) -> 0.098507463
A34: 33 | B34: 46531 | C34: Peak | D34: reduced | E34: Last big weekend (2 weeks out), then taper begins. | F34: =SUMIFS(Calendar!$G$2:$G$426,Calendar!$A$2:$A$426,$A34)/60 -> 14.5 | G34: =SUMIFS(Calendar!$G$2:$G$426,Calendar!$A$2:$A$426,$A34,Calendar!$E$2:$E$426,"Swim")/60 -> 2.8333333 | H34: =SUMIFS(Calendar!$G$2:$G$426,Calendar!$A$2:$A$426,$A34,Calendar!$E$2:$E$426,"Bike")/60 -> 7.0833333 | I34: =SUMIFS(Calendar!$G$2:$G$426,Calendar!$A$2:$A$426,$A34,Calendar!$E$2:$E$426,"Run")/60 -> 3.8333333 | J34: =SUMIFS(Calendar!$G$2:$G$426,Calendar!$A$2:$A$426,$A34,Calendar!$E$2:$E$426,"Strength")/60 -> 0.75 | K34: =SUMIFS(Calendar!$G$2:$G$426,Calendar!$A$2:$A$426,$A34,Calendar!$E$2:$E$426,"Race")/60 -> 0 | L34: =SUMIFS(Calendar!$H$2:$H$426,Calendar!$A$2:$A$426,$A34,Calendar!$E$2:$E$426,"Swim") -> 8.1 | M34: =SUMIFS(Calendar!$H$2:$H$426,Calendar!$A$2:$A$426,$A34,Calendar!$E$2:$E$426,"Run") -> 38.3 | N34: — | O34: — | P34: =IFERROR(SUMIFS(Calendar!$M$2:$M$426,Calendar!$A$2:$A$426,$A34)/((SUMIFS(Calendar!$G$2:$G$426,Calendar!$A$2:$A$426,$A34,Calendar!$E$2:$E$426,"Swim"))+(SUMIFS(Calendar!$G$2:$G$426,Calendar!$A$2:$A$426,$A34,Calendar!$E$2:$E$426,"Bike"))+(SUMIFS(Calendar!$G$2:$G$426,Calendar!$A$2:$A$426,$A34,Calendar!$E$2:$E$426,"Run"))),0) -> 0.071515152
A35: 34 | B35: 46538 | C35: Taper | D35: taper | E35: Taper (~60%): keep intensity, cut volume. Last strength session Mon. | F35: =SUMIFS(Calendar!$G$2:$G$426,Calendar!$A$2:$A$426,$A35)/60 -> 9.9166667 | G35: =SUMIFS(Calendar!$G$2:$G$426,Calendar!$A$2:$A$426,$A35,Calendar!$E$2:$E$426,"Swim")/60 -> 2.25 | H35: =SUMIFS(Calendar!$G$2:$G$426,Calendar!$A$2:$A$426,$A35,Calendar!$E$2:$E$426,"Bike")/60 -> 5 | I35: =SUMIFS(Calendar!$G$2:$G$426,Calendar!$A$2:$A$426,$A35,Calendar!$E$2:$E$426,"Run")/60 -> 2.3333333 | J35: =SUMIFS(Calendar!$G$2:$G$426,Calendar!$A$2:$A$426,$A35,Calendar!$E$2:$E$426,"Strength")/60 -> 0.33333333 | K35: =SUMIFS(Calendar!$G$2:$G$426,Calendar!$A$2:$A$426,$A35,Calendar!$E$2:$E$426,"Race")/60 -> 0 | L35: =SUMIFS(Calendar!$H$2:$H$426,Calendar!$A$2:$A$426,$A35,Calendar!$E$2:$E$426,"Swim") -> 6.4 | M35: =SUMIFS(Calendar!$H$2:$H$426,Calendar!$A$2:$A$426,$A35,Calendar!$E$2:$E$426,"Run") -> 23.3 | N35: — | O35: — | P35: =IFERROR(SUMIFS(Calendar!$M$2:$M$426,Calendar!$A$2:$A$426,$A35)/((SUMIFS(Calendar!$G$2:$G$426,Calendar!$A$2:$A$426,$A35,Calendar!$E$2:$E$426,"Swim"))+(SUMIFS(Calendar!$G$2:$G$426,Calendar!$A$2:$A$426,$A35,Calendar!$E$2:$E$426,"Bike"))+(SUMIFS(Calendar!$G$2:$G$426,Calendar!$A$2:$A$426,$A35,Calendar!$E$2:$E$426,"Run"))),0) -> 0.076521739
A36: 35 | B36: 46545 | C36: Taper | D36: race | E36: Race week — travel to Cairns, sleep, carb-load Fri–Sat (8–10 g/kg ≈ 640–800 g/day). | F36: =SUMIFS(Calendar!$G$2:$G$426,Calendar!$A$2:$A$426,$A36)/60 -> 16.916667 | G36: =SUMIFS(Calendar!$G$2:$G$426,Calendar!$A$2:$A$426,$A36,Calendar!$E$2:$E$426,"Swim")/60 -> 1.5833333 | H36: =SUMIFS(Calendar!$G$2:$G$426,Calendar!$A$2:$A$426,$A36,Calendar!$E$2:$E$426,"Bike")/60 -> 2.0833333 | I36: =SUMIFS(Calendar!$G$2:$G$426,Calendar!$A$2:$A$426,$A36,Calendar!$E$2:$E$426,"Run")/60 -> 1 | J36: =SUMIFS(Calendar!$G$2:$G$426,Calendar!$A$2:$A$426,$A36,Calendar!$E$2:$E$426,"Strength")/60 -> 0 | K36: =SUMIFS(Calendar!$G$2:$G$426,Calendar!$A$2:$A$426,$A36,Calendar!$E$2:$E$426,"Race")/60 -> 12.25 | L36: =SUMIFS(Calendar!$H$2:$H$426,Calendar!$A$2:$A$426,$A36,Calendar!$E$2:$E$426,"Swim") -> 4.3 | M36: =SUMIFS(Calendar!$H$2:$H$426,Calendar!$A$2:$A$426,$A36,Calendar!$E$2:$E$426,"Run") -> 10 | N36: — | O36: — | P36: =IFERROR(SUMIFS(Calendar!$M$2:$M$426,Calendar!$A$2:$A$426,$A36)/((SUMIFS(Calendar!$G$2:$G$426,Calendar!$A$2:$A$426,$A36,Calendar!$E$2:$E$426,"Swim"))+(SUMIFS(Calendar!$G$2:$G$426,Calendar!$A$2:$A$426,$A36,Calendar!$E$2:$E$426,"Bike"))+(SUMIFS(Calendar!$G$2:$G$426,Calendar!$A$2:$A$426,$A36,Calendar!$E$2:$E$426,"Run"))),0) -> 0.11785714
A38: Δ columns only apply to 'load' weeks and compare with the previous load week; red would flag >10%. Run-km cap applies from week 9, once continuous running is established. Totals are live SUMIFS from the Calendar, so editing a session updates this table.

Sheet Calendar
A1: Week | B1: Date | C1: Day | D1: Phase | E1: Sport | F1: Session | G1: Duration (min) | H1: Distance (km) | I1: Main set / details | J1: Target zone (HR / Power / Pace) | K1: RPE | L1: Fuel | M1: High-intensity min (Z4+) | N1: Done | O1: Notes | P1: When
A2: 1 | B2: 46307 | C2: Mon | D2: Transition | E2: Swim | F2: Aerobic endurance | G2: 50 | H2: 2.5 | I2: WU 300 easy + 4×50 build /15s. MS 4×400 @ 1:42–1:48/100m, 20s rest (every 2nd rep with pull buoy) + 200 steady pull. CD 200 easy. All reps ≥50m (Watch-safe). | J2: Z2 1:42–1:48/100m (IM pace 1:44) · RPE 3–4 | K2: 3–4 | M2: 0 | P2: Midday
A3: 1 | B3: 46308 | C3: Tue | D3: Transition | E3: Bike | F3: Intervals — Z5 VO2max | G3: 60 | H3: 30 | I3: Zwift structured. WU 15' Z1→Z2 incl. 3×30s @ 100+rpm. MS 4×3' @ 254–271W (105–112% FTP) /3' easy. Remaining time Z2 (150–170W). CD 5–10' easy. Cadence 85–100 on efforts. | J3: Z5 VO2max: 254–271W (105–112% FTP) · easy between Z1 <133W (<55%) · HR <130 · RPE 1–2 | K3: 8–9 | L3: Water/electrolytes only | M3: 12 | P3: AM
A4: 1 | B4: 46308 | C4: Tue | D4: Transition | E4: Strength | F4: Strength A — base | G4: 40 | I4: Do this AFTER the bike intervals — ideally 6h+ later (bike AM, gym PM). Lower — max strength & bone loading: back squat or trap-bar DL 4×6, Bulgarian split squat 3×8/leg, seated soleus raise 3×12 heavy, single-leg calf raise 3×15, tibialis raise 3×15, pogo hops 3×20 (progress to single-leg hops from wk 8), Copenhagen plank 3×20s. See Strength tab. | J4: RPE 7–8 on main lifts, 1–3 reps in reserve | K4: 7–8 | M4: 0 | P4: PM
A5: 1 | B5: 46309 | C5: Wed | D5: Transition | E5: Swim | F5: CSS / threshold | G5: 50 | H5: 2.4 | I5: WU 400 + 4×50 build /15s. MS 14×100 @ CSS 1:32–1:36 /15s + 4×50 @ ≤1:30 /20s. CD 200 easy (+200 pull if time). | J5: Z4 CSS 1:32–1:36/100m · RPE 7; 50s Z5 ≤1:30/100m · RPE 8–9 | K5: 7–8 | M5: 23 | P5: Midday
A6: 1 | B6: 46310 | C6: Thu | D6: Transition | E6: Bike | F6: Endurance ride | G6: 60 | H6: 30 | I6: Zwift endurance. 10' WU 120→150W, 45' steady @ 150–175W, cadence 85–95, 5' easy. | J6: Z2 150–175W (62–72%) · HR 130–143 · RPE 3–4 | K6: 3–4 | L6: Water/electrolytes only | M6: 0 | P6: AM
A7: 1 | B7: 46310 | C7: Thu | D7: Transition | E7: Strength | F7: Strength B — base | G7: 35 | I7: Posterior chain + upper: Romanian DL 3×8, hip thrust 3×10, step-ups 3×8/leg, pull-ups 4×6, push-ups or DB press 3×10, single-arm row 3×10, Pallof press 3×10, dead bug 3×10. See Strength tab. | J7: RPE 7–8 on main lifts, 1–3 reps in reserve | K7: 7–8 | M7: 0 | P7: PM
A8: 1 | B8: 46311 | C8: Fri | D8: Transition | E8: Swim | F8: Long aerobic swim | G8: 45 | H8: 2.2 | I8: WU 400 easy. MS 3×500 @ 1:42–1:48/100m /30s + 100 easy. CD 200. Hold pace — the goal is aerobic durability, not speed. | J8: Z2 1:42–1:48/100m (IM pace 1:44) · RPE 3–4 | K8: 3–4 | M8: 0 | P8: Midday
A9: 1 | B9: 46312 | C9: Sat | D9: Transition | E9: Bike | F9: Long ride | G9: 80 | H9: 40 | I9: Long ride 1h20. First 20' Z1–low Z2, then Z2 150–175W. Smooth, steady, seated. Indoors until your outdoor kit is sorted; once outdoors, pick flat, low-traffic roads and keep the same power. | J9: Z2 150–175W (62–72%) · HR 130–143 · RPE 3–4; blocks IM power 160–172W (66–71%) · HR ≤143 · RPE 4 | K9: 3–4 | L9: 60–70 g carbs/h from minute 20 · 500–800mg sodium/h · 500–750ml fluid/h (gut training) | M9: 0 | P9: AM
A10: 1 | B10: 46313 | C10: Sun | D10: Transition | E10: Bike | F10: Recovery spin | G10: 40 | H10: 18 | I10: Easy spin, 40' at high cadence (90–100 rpm). Replaces a 4th swim — keeps the legs moving after Saturday's long ride. | J10: Z1 <133W (<55%) · HR <130 · RPE 1–2 | K10: 1–2 | L10: Water/electrolytes only | M10: 0 | P10: AM
A11: 2 | B11: 46314 | C11: Mon | D11: Transition | E11: Swim | F11: Aerobic endurance | G11: 45 | H11: 2.2 | I11: WU 300 easy + 4×50 build /15s. MS 3×400 @ 1:42–1:48/100m, 20s rest (every 2nd rep with pull buoy) + 300 steady pull. CD 200 easy. All reps ≥50m (Watch-safe). | J11: Z2 1:42–1:48/100m (IM pace 1:44) · RPE 3–4 | K11: 3–4 | M11: 0 | P11: Midday
A12: 2 | B12: 46314 | C12: Mon | D12: Transition | E12: Strength | F12: Strength A — base | G12: 30 | I12: Lower — max strength & bone loading: back squat or trap-bar DL 4×6, Bulgarian split squat 3×8/leg, seated soleus raise 3×12 heavy, single-leg calf raise 3×15, tibialis raise 3×15, pogo hops 3×20 (progress to single-leg hops from wk 8), Copenhagen plank 3×20s. See Strength tab. | J12: RPE 7–8 on main lifts, 1–3 reps in reserve | K12: 7–8 | M12: 0 | P12: PM
A13: 2 | B13: 46315 | C13: Tue | D13: Transition | E13: Bike | F13: Endurance ride | G13: 60 | H13: 30 | I13: Zwift endurance. 10' WU 120→150W, 45' steady @ 150–175W, cadence 85–95, 5' easy. | J13: Z2 150–175W (62–72%) · HR 130–143 · RPE 3–4 | K13: 3–4 | L13: Water/electrolytes only | M13: 0 | P13: AM
A14: 2 | B14: 46316 | C14: Wed | D14: Transition | E14: Swim | F14: CSS / threshold | G14: 45 | H14: 2.1 | I14: WU 400 + 4×50 build /15s. MS 11×100 @ CSS 1:32–1:36 /15s + 4×50 @ ≤1:30 /20s. CD 200 easy (+200 pull if time). | J14: Z4 CSS 1:32–1:36/100m · RPE 7; 50s Z5 ≤1:30/100m · RPE 8–9 | K14: 7–8 | M14: 19 | P14: Midday
A15: 2 | B15: 46317 | C15: Thu | D15: Transition | E15: Bike | F15: Recovery spin | G15: 45 | H15: 20 | I15: Easy spin, 45' at high cadence (90–100 rpm). Keep it light. | J15: Z1 <133W (<55%) · HR <130 · RPE 1–2 | K15: 1–2 | L15: Water/electrolytes only | M15: 0 | P15: AM
A16: 2 | B16: 46318 | C16: Fri | D16: Transition | E16: Rest | F16: Rest | G16: 0 | I16: Wedding day 🎉 | J16: — | K16: — | M16: 0
A17: 2 | B17: 46319 | C17: Sat | D17: Transition | E17: Rest | F17: Rest | G17: 0 | I17: Rest day — sleep, walk, mobility. | J17: — | K17: — | M17: 0
A18: 2 | B18: 46320 | C18: Sun | D18: Transition | E18: Bike | F18: Endurance ride | G18: 60 | H18: 30 | I18: Zwift endurance. 10' WU 120→150W, 45' steady @ 150–175W, cadence 85–95, 5' easy. | J18: Z2 150–175W (62–72%) · HR 130–143 · RPE 3–4 | K18: 3–4 | L18: Water/electrolytes only | M18: 0 | P18: AM
A19: 3 | B19: 46321 | C19: Mon | D19: Base 1 | E19: Swim | F19: Aerobic endurance | G19: 45 | H19: 2.2 | I19: WU 300 easy + 4×50 build /15s. MS 3×400 @ 1:42–1:48/100m, 20s rest (every 2nd rep with pull buoy) + 300 steady pull. CD 200 easy. All reps ≥50m (Watch-safe). | J19: Z2 1:42–1:48/100m (IM pace 1:44) · RPE 3–4 | K19: 3–4 | M19: 0 | P19: Midday
A20: 3 | B20: 46321 | C20: Mon | D20: Base 1 | E20: Run | F20: Walk-run (stage 1) | G20: 20 | H20: 1 | I20: RETURN-TO-RUN stage 1: 5' brisk walk, 6×(1' run / 1' walk), finish with walk. Flat, soft surface (grass/path), short quick steps (cadence +5%). Alternate days only. Bone rule: pain ≤2/10 during, none next morning — else stop, 2 days off, drop back one stage. | J20: Z1 HR ≤141 · RPE 2–3 | K20: 2–3 | L20: Water/electrolytes only | M20: 0 | P20: AM
A21: 3 | B21: 46322 | C21: Tue | D21: Base 1 | E21: Bike | F21: Intervals — Z5 VO2max | G21: 60 | H21: 30 | I21: Zwift structured. WU 15' Z1→Z2 incl. 3×30s @ 100+rpm. MS 5×3' @ 266–281W (110–115% FTP) /3' easy. Remaining time Z2 (150–170W). CD 5–10' easy. Cadence 85–100 on efforts. | J21: Z5 VO2max: 266–281W (110–115% FTP) · easy between Z1 <133W (<55%) · HR <130 · RPE 1–2 | K21: 8–9 | L21: Water/electrolytes only | M21: 15 | P21: AM
A22: 3 | B22: 46322 | C22: Tue | D22: Base 1 | E22: Strength | F22: Strength A — base | G22: 40 | I22: Do this AFTER the bike intervals — ideally 6h+ later (bike AM, gym PM). Lower — max strength & bone loading: back squat or trap-bar DL 4×6, Bulgarian split squat 3×8/leg, seated soleus raise 3×12 heavy, single-leg calf raise 3×15, tibialis raise 3×15, pogo hops 3×20 (progress to single-leg hops from wk 8), Copenhagen plank 3×20s. See Strength tab. | J22: RPE 7–8 on main lifts, 1–3 reps in reserve | K22: 7–8 | M22: 0 | P22: PM
A23: 3 | B23: 46323 | C23: Wed | D23: Base 1 | E23: Swim | F23: CSS / threshold | G23: 50 | H23: 2.4 | I23: WU 400 + 4×50 build /15s. MS 14×100 @ CSS 1:32–1:36 /15s + 4×50 @ ≤1:30 /20s. CD 200 easy (+200 pull if time). | J23: Z4 CSS 1:32–1:36/100m · RPE 7; 50s Z5 ≤1:30/100m · RPE 8–9 | K23: 7–8 | M23: 23 | P23: Midday
A24: 3 | B24: 46323 | C24: Wed | D24: Base 1 | E24: Run | F24: Walk-run (stage 1) | G24: 20 | H24: 1 | I24: RETURN-TO-RUN stage 1: 5' brisk walk, 6×(1' run / 1' walk), finish with walk. Flat, soft surface (grass/path), short quick steps (cadence +5%). Alternate days only. Bone rule: pain ≤2/10 during, none next morning — else stop, 2 days off, drop back one stage. | J24: Z1 HR ≤141 · RPE 2–3 | K24: 2–3 | L24: Water/electrolytes only | M24: 0 | P24: AM
A25: 3 | B25: 46324 | C25: Thu | D25: Base 1 | E25: Bike | F25: Endurance ride | G25: 45 | H25: 22 | I25: Zwift endurance. 10' WU 120→150W, 30' steady @ 150–175W, cadence 85–95, 5' easy. | J25: Z2 150–175W (62–72%) · HR 130–143 · RPE 3–4 | K25: 3–4 | L25: Water/electrolytes only | M25: 0 | P25: AM
